Workbook
Name _03_06_2024: 'Engagement Summary'!$A$3:$A$201
Name _15_06_2024: 'Campaign Metadata'!$B$3:$B$5
Name _15_07_2024: 'Campaign Metadata'!$C$3:$C$5
Name _23_12_2024: 'Task 1'!$C$3:$C$340
Name AnytimeIsTeslaTime: 'Task 1'!#REF!
Name Check_out_our_latest_reel_on_twitter: 'Task 1'!$E$3:$E$340
Name CybertruckLaunch: 'Campaign Metadata'!$A$3:$A$5
Name CybertruckLaunch: 'Task 1'!$M$3:$M$340
Name EVRevolution__TeslaCoInnovation: 'Campaign Metadata'!$G$3:$G$5
Name FutureOfDriving: 'Task 1'!#REF!
Name Instagram: 'Engagement Summary'!$B$3:$B$201
Name Instagram_Facebook: 'Campaign Metadata'!$F$3:$F$5
Name P001_: 'Task 1'!$A$3:$A$340
Name Product_Awareness: 'Campaign Metadata'!$D$3:$D$5
Name Reel: 'Task 1'!$D$3:$D$340
Name Slicer_Platform: #N/A
Name Slicer_Platform1: #N/A
Name Slicer_Platform2: #N/A
Name Slicer_Platform3: #N/A
Name Twitter: 'Task 1'!$B$3:$B$340

Sheet Post
A1: Post ID | B1: Platform | C1: Date | D1: Content Type | E1: Post Text | F1: Likes | G1: Shares | H1: Comments | I1: Impressions | J1: Reach | K1: Clicks | L1: Hashtags Used | M1: Campaign_Name | N1: Engagement Rate | O1: Content Objective | P1: Campaign Period
A2: P105 | B2: Instagram | C2: 45457 | D2: Carousel | E2: Check out our latest carousel on instagram! | F2: 498 | G2: 38 | H2: 42 | I2: 4482 | J2: 3647 | K2: 32 | L2: #FutureOfDriving | M2: CybertruckLaunch | N2: =(Posts1116[[#This Row],[Likes]]+Posts1116[[#This Row],[Shares]]+Posts1116[[#This Row],[Comments]])/Posts1116[[#This Row],[Impressions]] -> 0.12896029 | O2: =_xlfn.XLOOKUP(Posts1116[[#This Row],[Campaign_Name]],Campaign_Metadata[Campaign_Name],Campaign_Metadata[Objective]) -> Product Awareness | P2: =IF(AND(Posts1116[[#This Row],[Date]]>=DATE(2024,6,15), Posts1116[[#This Row],[Date]]<=DATE(2024,7,15)),"During", "Before") -> Before
A3: P123 | B3: Instagram | C3: 45457 | D3: Story | E3: Check out our latest story on instagram! | F3: 4363 | G3: 649 | H3: 140 | I3: 21815 | J3: 21481 | K3: 157 | L3: #EVRevolution | M3: CybertruckLaunch | N3: =(Posts1116[[#This Row],[Likes]]+Posts1116[[#This Row],[Shares]]+Posts1116[[#This Row],[Comments]])/Posts1116[[#This Row],[Impressions]] -> 0.23616777 | O3: =_xlfn.XLOOKUP(Posts1116[[#This Row],[Campaign_Name]],Campaign_Metadata[Campaign_Name],Campaign_Metadata[Objective]) -> Product Awareness | P3: =IF(AND(Posts1116[[#This Row],[Date]]>=DATE(2024,6,15), Posts1116[[#This Row],[Date]]<=DATE(2024,7,15)),"During", "Before") -> Before
A4: P149 | B4: Twitter | C4: 45459 | D4: Video | E4: Check out our latest video on twitter! | F4: 1702 | G4: 750 | H4: 179 | I4: 34040 | J4: 33174 | K4: 76 | L4: #EVRevolution | M4: CybertruckLaunch | N4: =(Posts1116[[#This Row],[Likes]]+Posts1116[[#This Row],[Shares]]+Posts1116[[#This Row],[Comments]])/Posts1116[[#This Row],[Impressions]] -> 0.077291422 | O4: =_xlfn.XLOOKUP(Posts1116[[#This Row],[Campaign_Name]],Campaign_Metadata[Campaign_Name],Campaign_Metadata[Objective]) -> Product Awareness | P4: =IF(AND(Posts1116[[#This Row],[Date]]>=DATE(2024,6,15), Posts1116[[#This Row],[Date]]<=DATE(2024,7,15)),"During", "Before") -> During
A5: P176 | B5: Facebook | C5: 45463 | D5: Video | E5: Check out our latest video on facebook! | F5: 3798 | G5: 31 | H5: 279 | I5: 75960 | J5: 75813 | K5: 266 | L5: #TeslaCoInnovation | M5: CybertruckLaunch | N5: =(Posts1116[[#This Row],[Likes]]+Posts1116[[#This Row],[Shares]]+Posts1116[[#This Row],[Comments]])/Posts1116[[#This Row],[Impressions]] -> 0.054081095 | O5: =_xlfn.XLOOKUP(Posts1116[[#This Row],[Campaign_Name]],Campaign_Metadata[Campaign_Name],Campaign_Metadata[Objective]) -> Product Awareness | P5: =IF(AND(Posts1116[[#This Row],[Date]]>=DATE(2024,6,15), Posts1116[[#This Row],[Date]]<=DATE(2024,7,15)),"During", "Before") -> During
A6: P206 | B6: Twitter | C6: 45467 | D6: Text | E6: Check out our latest text on twitter! | F6: 941 | G6: 121 | H6: 458 | I6: 14115 | J6: 13838 | K6: 87 | L6: #EVRevolution | M6: CybertruckLaunch | N6: =(Posts1116[[#This Row],[Likes]]+Posts1116[[#This Row],[Shares]]+Posts1116[[#This Row],[Comments]])/Posts1116[[#This Row],[Impressions]] -> 0.10768686 | O6: =_xlfn.XLOOKUP(Posts1116[[#This Row],[Campaign_Name]],Campaign_Metadata[Campaign_Name],Campaign_Metadata[Objective]) -> Product Awareness | P6: =IF(AND(Posts1116[[#This Row],[Date]]>=DATE(2024,6,15), Posts1116[[#This Row],[Date]]<=DATE(2024,7,15)),"During", "Before") -> During
A7: P005 | B7: YouTube | C7: 45469 | D7: Reel | E7: Check out our latest reel on youtube! | F7: 3557 | G7: 687 | H7: 424 | I7: 71140 | J7: 70701 | K7: 224 | L7: #EVRevolution | M7: CybertruckLaunch | N7: =(Posts1116[[#This Row],[Likes]]+Posts1116[[#This Row],[Shares]]+Posts1116[[#This Row],[Comments]])/Posts1116[[#This Row],[Impressions]] -> 0.065617093 | O7: =_xlfn.XLOOKUP(Posts1116[[#This Row],[Campaign_Name]],Campaign_Metadata[Campaign_Name],Campaign_Metadata[Objective]) -> Product Awareness | P7: =IF(AND(Posts1116[[#This Row],[Date]]>=DATE(2024,6,15), Posts1116[[#This Row],[Date]]<=DATE(2024,7,15)),"During", "Before") -> During
A8: P005 | B8: YouTube | C8: 45469 | D8: Reel | E8: Check out our latest reel on youtube! | F8: 3557 | G8: 687 | H8: 424 | I8: 71140 | J8: 70701 | K8: 224 | L8: #TeslaCoInnovation | M8: CybertruckLaunch | N8: =(Posts1116[[#This Row],[Likes]]+Posts1116[[#This Row],[Shares]]+Posts1116[[#This Row],[Comments]])/Posts1116[[#This Row],[Impressions]] -> 0.065617093 | O8: =_xlfn.XLOOKUP(Posts1116[[#This Row],[Campaign_Name]],Campaign_Metadata[Campaign_Name],Campaign_Metadata[Objective]) -> Product Awareness | P8: =IF(AND(Posts1116[[#This Row],[Date]]>=DATE(2024,6,15), Posts1116[[#This Row],[Date]]<=DATE(2024,7,15)),"During", "Before") -> During
A9: P228 | B9: Instagram | C9: 45474 | D9: Story | E9: Check out our latest story on instagram! | F9: 4808 | G9: 772 | H9: 320 | I9: 72120 | J9: 71696 | K9: 195 | L9: #EVRevolution | M9: CybertruckLaunch | N9: =(Posts1116[[#This Row],[Likes]]+Posts1116[[#This Row],[Shares]]+Posts1116[[#This Row],[Comments]])/Posts1116[[#This Row],[Impressions]] -> 0.081808098 | O9: =_xlfn.XLOOKUP(Posts1116[[#This Row],[Campaign_Name]],Campaign_Metadata[Campaign_Name],Campaign_Metadata[Objective]) -> Product Awareness | P9: =IF(AND(Posts1116[[#This Row],[Date]]>=DATE(2024,6,15), Posts1116[[#This Row],[Date]]<=DATE(2024,7,15)),"During", "Before") -> During
A10: P066 | B10: Twitter | C10: 45499 | D10: Carousel | E10: Check out our latest carousel on twitter! | F10: 432 | G10: 171 | H10: 280 | I10: 3024 | J10: 2285 | K10: 184 | L10: #EVRevolution | M10: CybertruckLaunch | N10: =(Posts1116[[#This Row],[Likes]]+Posts1116[[#This Row],[Shares]]+Posts1116[[#This Row],[Comments]])/Posts1116[[#This Row],[Impressions]] -> 0.29199735 | O10: =_xlfn.XLOOKUP(Posts1116[[#This Row],[Campaign_Name]],Campaign_Metadata[Campaign_Name],Campaign_Metadata[Objective]) -> Product Awareness | P10: =IF(AND(Posts1116[[#This Row],[Date]]>=DATE(2024,6,15), Posts1116[[#This Row],[Date]]<=DATE(2024,7,15)),"During", "Before") -> Before
A11: P151 | B11: Instagram | C11: 45499 | D11: Image | E11: Check out our latest image on instagram! | F11: 3559 | G11: 59 | H11: 289 | I11: 35590 | J11: 35105 | K11: 122 | L11: #EVRevolution | M11: CybertruckLaunch | N11: =(Posts1116[[#This Row],[Likes]]+Posts1116[[#This Row],[Shares]]+Posts1116[[#This Row],[Comments]])/Posts1116[[#This Row],[Impressions]] -> 0.10977803 | O11: =_xlfn.XLOOKUP(Posts1116[[#This Row],[Campaign_Name]],Campaign_Metadata[Campaign_Name],Campaign_Metadata[Objective]) -> Product Awareness | P11: =IF(AND(Posts1116[[#This Row],[Date]]>=DATE(2024,6,15), Posts1116[[#This Row],[Date]]<=DATE(2024,7,15)),"During", "Before") -> Before
A12: P184 | B12: Twitter | C12: 45501 | D12: Image | E12: Check out our latest image on twitter! | F12: 3215 | G12: 960 | H12: 202 | I12: 32150 | J12: 31404 | K12: 251 | L12: #EVRevolution | M12: CybertruckLaunch | N12: =(Posts1116[[#This Row],[Likes]]+Posts1116[[#This Row],[Shares]]+Posts1116[[#This Row],[Comments]])/Posts1116[[#This Row],[Impressions]] -> 0.13614308 | O12: =_xlfn.XLOOKUP(Posts1116[[#This Row],[Campaign_Name]],Campaign_Metadata[Campaign_Name],Campaign_Metadata[Objective]) -> Product Awareness | P12: =IF(AND(Posts1116[[#This Row],[Date]]>=DATE(2024,6,15), Posts1116[[#This Row],[Date]]<=DATE(2024,7,15)),"During", "Before") -> Before
A13: P032 | B13: Twitter | C13: 45504 | D13: Carousel | E13: Check out our latest carousel on twitter! | F13: 2278 | G13: 10 | H13: 321 | I13: 13668 | J13: 12676 | K13: 275 | L13: #EVRevolution | M13: CybertruckLaunch | N13: =(Posts1116[[#This Row],[Likes]]+Posts1116[[#This Row],[Shares]]+Posts1116[[#This Row],[Comments]])/Posts1116[[#This Row],[Impressions]] -> 0.19088382 | O13: =_xlfn.XLOOKUP(Posts1116[[#This Row],[Campaign_Name]],Campaign_Metadata[Campaign_Name],Campaign_Metadata[Objective]) -> Product Awareness | P13: =IF(AND(Posts1116[[#This Row],[Date]]>=DATE(2024,6,15), Posts1116[[#This Row],[Date]]<=DATE(2024,7,15)),"During", "Before") -> Before
... A279: P115 | B279: Twitter | C279: 45788 | D279: Image | E279: Check out our latest image on twitter! | F279: 2493 | G279: 97 | H279: 44 | I279: 42381 | J279: 41991 | K279: 242 | L279: #AnytimeIsTeslaTime | M279: SustainabilityDrive | N279: =(Posts1116[[#This Row],[Likes]]+Posts1116[[#This Row],[Shares]]+Posts1116[[#This Row],[Comments]])/Posts1116[[#This Row],[Impressions]] -> 0.062150492 | O279: =_xlfn.XLOOKUP(Posts1116[[#This Row],[Campaign_Name]],Campaign_Metadata[Campaign_Name],Campaign_Metadata[Objective]) -> Community Growth | P279: =IF(AND(Posts1116[[#This Row],[Date]]>=DATE(2024,6,15), Posts1116[[#This Row],[Date]]<=DATE(2024,7,15)),"During", "Before") -> Before
A280: P234 | B280: Facebook | C280: 45444 | D280: Text | E280: Check out our latest text on facebook! | F280: 1272 | G280: 465 | H280: 99 | I280: 24168 | J280: 23719 | K280: 42 | L280: #TeslaCoInnovation | N280: =(Posts1116[[#This Row],[Likes]]+Posts1116[[#This Row],[Shares]]+Posts1116[[#This Row],[Comments]])/Posts1116[[#This Row],[Impressions]] -> 0.075968222 | O280: =_xlfn.XLOOKUP(Posts1116[[#This Row],[Campaign_Name]],Campaign_Metadata[Campaign_Name],Campaign_Metadata[Objective]) -> #N/A | P280: =IF(AND(Posts1116[[#This Row],[Date]]>=DATE(2024,6,15), Posts1116[[#This Row],[Date]]<=DATE(2024,7,15)),"During", "Before") -> Before
A281: P220 | B281: Instagram | C281: 45445 | D281: Story | E281: Check out our latest story on instagram! | F281: 84 | G281: 897 | H281: 85 | I281: 588 | J281: 8 | K281: 12 | L281: #EVRevolution | N281: =(Posts1116[[#This Row],[Likes]]+Posts1116[[#This Row],[Shares]]+Posts1116[[#This Row],[Comments]])/Posts1116[[#This Row],[Impressions]] -> 1.8129252 | O281: =_xlfn.XLOOKUP(Posts1116[[#This Row],[Campaign_Name]],Campaign_Metadata[Campaign_Name],Campaign_Metadata[Objective]) -> #N/A | P281: =IF(AND(Posts1116[[#This Row],[Date]]>=DATE(2024,6,15), Posts1116[[#This Row],[Date]]<=DATE(2024,7,15)),"During", "Before") -> Before
A282: P146 | B282: YouTube | C282: 45448 | D282: Reel | E282: Check out our latest reel on youtube! | F282: 3065 | G282: 772 | H282: 142 | I282: 18390 | J282: 17875 | K282: 200 | L282: #EVRevolution | N282: =(Posts1116[[#This Row],[Likes]]+Posts1116[[#This Row],[Shares]]+Posts1116[[#This Row],[Comments]])/Posts1116[[#This Row],[Impressions]] -> 0.21636759 | O282: =_xlfn.XLOOKUP(Posts1116[[#This Row],[Campaign_Name]],Campaign_Metadata[Campaign_Name],Campaign_Metadata[Objective]) -> #N/A | P282: =IF(AND(Posts1116[[#This Row],[Date]]>=DATE(2024,6,15), Posts1116[[#This Row],[Date]]<=DATE(2024,7,15)),"During", "Before") -> Before
A283: P146 | B283: YouTube | C283: 45448 | D283: Reel | E283: Check out our latest reel on youtube! | F283: 3065 | G283: 772 | H283: 142 | I283: 18390 | J283: 17875 | K283: 200 | L283: #AnytimeIsTeslaTime | N283: =(Posts1116[[#This Row],[Likes]]+Posts1116[[#This Row],[Shares]]+Posts1116[[#This Row],[Comments]])/Posts1116[[#This Row],[Impressions]] -> 0.21636759 | O283: =_xlfn.XLOOKUP(Posts1116[[#This Row],[Campaign_Name]],Campaign_Metadata[Campaign_Name],Campaign_Metadata[Objective]) -> #N/A | P283: =IF(AND(Posts1116[[#This Row],[Date]]>=DATE(2024,6,15), Posts1116[[#This Row],[Date]]<=DATE(2024,7,15)),"During", "Before") -> Before
A284: P080 | B284: Instagram | C284: 45456 | D284: Story | E284: Check out our latest story on instagram! | F284: 2103 | G284: 892 | H284: 103 | I284: 39957 | J284: 39466 | K284: 28 | L284: #FutureOfDriving | N284: =(Posts1116[[#This Row],[Likes]]+Posts1116[[#This Row],[Shares]]+Posts1116[[#This Row],[Comments]])/Posts1116[[#This Row],[Impressions]] -> 0.077533348 | O284: =_xlfn.XLOOKUP(Posts1116[[#This Row],[Campaign_Name]],Campaign_Metadata[Campaign_Name],Campaign_Metadata[Objective]) -> #N/A | P284: =IF(AND(Posts1116[[#This Row],[Date]]>=DATE(2024,6,15), Posts1116[[#This Row],[Date]]<=DATE(2024,7,15)),"During", "Before") -> Before
A285: P225 | B285: Twitter | C285: 45463 | D285: Carousel | E285: Check out our latest carousel on twitter! | F285: 4672 | G285: 325 | H285: 32 | I285: 88768 | J285: 87833 | K285: 118 | L285: #EVRevolution | N285: =(Posts1116[[#This Row],[Likes]]+Posts1116[[#This Row],[Shares]]+Posts1116[[#This Row],[Comments]])/Posts1116[[#This Row],[Impressions]] -> 0.056653298 | O285: =_xlfn.XLOOKUP(Posts1116[[#This Row],[Campaign_Name]],Campaign_Metadata[Campaign_Name],Campaign_Metadata[Objective]) -> #N/A | P285: =IF(AND(Posts1116[[#This Row],[Date]]>=DATE(2024,6,15), Posts1116[[#This Row],[Date]]<=DATE(2024,7,15)),"During", "Before") -> During
A286: P107 | B286: YouTube | C286: 45464 | D286: Image | E286: Check out our latest image on youtube! | F286: 4832 | G286: 893 | H286: 10 | I286: 91808 | J286: 91296 | K286: 182 | L286: #TeslaCoInnovation | N286: =(Posts1116[[#This Row],[Likes]]+Posts1116[[#This Row],[Shares]]+Posts1116[[#This Row],[Comments]])/Posts1116[[#This Row],[Impressions]] -> 0.062467323 | O286: =_xlfn.XLOOKUP(Posts1116[[#This Row],[Campaign_Name]],Campaign_Metadata[Campaign_Name],Campaign_Metadata[Objective]) -> #N/A | P286: =IF(AND(Posts1116[[#This Row],[Date]]>=DATE(2024,6,15), Posts1116[[#This Row],[Date]]<=DATE(2024,7,15)),"During", "Before") -> During
A287: P059 | B287: Instagram | C287: 45465 | D287: Text | E287: Check out our latest text on instagram! | F287: 2180 | G287: 263 | H287: 387 | I287: 30520 | J287: 30059 | K287: 174 | L287: #EVRevolution | N287: =(Posts1116[[#This Row],[Likes]]+Posts1116[[#This Row],[Shares]]+Posts1116[[#This Row],[Comments]])/Posts1116[[#This Row],[Impressions]] -> 0.092726081 | O287: =_xlfn.XLOOKUP(Posts1116[[#This Row],[Campaign_Name]],Campaign_Metadata[Campaign_Name],Campaign_Metadata[Objective]) -> #N/A | P287: =IF(AND(Posts1116[[#This Row],[Date]]>=DATE(2024,6,15), Posts1116[[#This Row],[Date]]<=DATE(2024,7,15)),"During", "Before") -> During
A288: P174 | B288: Facebook | C288: 45465 | D288: Text | E288: Check out our latest text on facebook! | F288: 3828 | G288: 148 | H288: 253 | I288: 30624 | J288: 30229 | K288: 235 | L288: #EVRevolution | N288: =(Posts1116[[#This Row],[Likes]]+Posts1116[[#This Row],[Shares]]+Posts1116[[#This Row],[Comments]])/Posts1116[[#This Row],[Impressions]] -> 0.13809431 | O288: =_xlfn.XLOOKUP(Posts1116[[#This Row],[Campaign_Name]],Campaign_Metadata[Campaign_Name],Campaign_Metadata[Objective]) -> #N/A | P288: =IF(AND(Posts1116[[#This Row],[Date]]>=DATE(2024,6,15), Posts1116[[#This Row],[Date]]<=DATE(2024,7,15)),"During", "Before") -> During
A289: P250 | B289: Facebook | C289: 45465 | D289: Reel | E289: Check out our latest reel on facebook! | F289: 3813 | G289: 935 | H289: 274 | I289: 68634 | J289: 68488 | K289: 251 | L289: #FutureOfDriving | N289: =(Posts1116[[#This Row],[Likes]]+Posts1116[[#This Row],[Shares]]+Posts1116[[#This Row],[Comments]])/Posts1116[[#This Row],[Impressions]] -> 0.073170732 | O289: =_xlfn.XLOOKUP(Posts1116[[#This Row],[Campaign_Name]],Campaign_Metadata[Campaign_Name],Campaign_Metadata[Objective]) -> #N/A | P289: =IF(AND(Posts1116[[#This Row],[Date]]>=DATE(2024,6,15), Posts1116[[#This Row],[Date]]<=DATE(2024,7,15)),"During", "Before") -> During
A290: P229 | B290: Instagram | C290: 45476 | D290: Carousel | E290: Check out our latest carousel on instagram! | F290: 4799 | G290: 694 | H290: 289 | I290: 43191 | J290: 42228 | K290: 118 | L290: #TeslaCoInnovation | N290: =(Posts1116[[#This Row],[Likes]]+Posts1116[[#This Row],[Shares]]+Posts1116[[#This Row],[Comments]])/Posts1116[[#This Row],[Impressions]] -> 0.13387048 | O290: =_xlfn.XLOOKUP(Posts1116[[#This Row],[Campaign_Name]],Campaign_Metadata[Campaign_Name],Campaign_Metadata[Objective]) -> #N/A | P290: =IF(AND(Posts1116[[#This Row],[Date]]>=DATE(2024,6,15), Posts1116[[#This Row],[Date]]<=DATE(2024,7,15)),"During", "Before") -> During
A291: P179 | B291: Facebook | C291: 45488 | D291: Carousel | E291: Check out our latest carousel on facebook! | F291: 3796 | G291: 667 | H291: 395 | I291: 64532 | J291: 63550 | K291: 292 | L291: #TeslaCoInnovation | N291: =(Posts1116[[#This Row],[Likes]]+Posts1116[[#This Row],[Shares]]+Posts1116[[#This Row],[Comments]])/Posts1116[[#This Row],[Impressions]] -> 0.075280481 | O291: =_xlfn.XLOOKUP(Posts1116[[#This Row],[Campaign_Name]],Campaign_Metadata[Campaign_Name],Campaign_Metadata[Objective]) -> #N/A | P291: =IF(AND(Posts1116[[#This Row],[Date]]>=DATE(2024,6,15), Posts1116[[#This Row],[Date]]<=DATE(2024,7,15)),"During", "Before") -> During
... A340: P025 | B340: Twitter | C340: 45757 | D340: Carousel | E340: Check out our latest carousel on twitter! | F340: 3128 | G340: 211 | H340: 197 | I340: 59432 | J340: 59182 | K340: 238 | L340: #EVRevolution | N340: =(Posts1116[[#This Row],[Likes]]+Posts1116[[#This Row],[Shares]]+Posts1116[[#This Row],[Comments]])/Posts1116[[#This Row],[Impressions]] -> 0.059496568 | O340: =_xlfn.XLOOKUP(Posts1116[[#This Row],[Campaign_Name]],Campaign_Metadata[Campaign_Name],Campaign_Metadata[Objective]) -> #N/A | P340: =IF(AND(Posts1116[[#This Row],[Date]]>=DATE(2024,6,15), Posts1116[[#This Row],[Date]]<=DATE(2024,7,15)),"During", "Before") -> Before

Sheet Campaign Metadata
A1: Campaign_Name | B1: Start_Date | C1: End_Date | D1: Objective | E1: Total_Budget | F1: Target_Platforms | G1: Primary_Hashtags
A2: CybertruckLaunch | B2: 45458 | C2: 45488 | D2: Product Awareness | E2: 150000 | F2: Instagram,Facebook | G2: #EVRevolution,#TeslaCoInnovation
A3: ModelYCampaign | B3: 45566 | C3: 45596 | D3: Customer Engagement | E3: 200000 | F3: Instagram,YouTube | G3: #AnytimeIsTeslaTime,
A4: FSDUpdate | B4: 45651 | C4: 45667 | D4: Vehicle Launch | E4: 250000 | F4: Facebook,Twitter | G4: #SmoothLikeNitroTesla
A5: SustainabilityDrive | B5: 45717 | C5: 45747 | D5: Community Growth | E5: 180000 | F5: Instagram,Twitter | G5: #BetterWithTesla,#FutureOfDriving

Sheet Engagement Summary
A1: Week_Start_Date | B1: Platform | C1: New_Followers | D1: Unfollows | E1: Total_Followers | F1: Engagement_Rate | G1: Ad_Spend | H1: Net new follower | I1: Net follower growth rate | J1: Campaign
A2: 45446 | B2: Instagram | C2: 1135 | D2: 88 | E2: 344084 | F2: 8.06 | G2: 5904 | H2: =Engagement_Summary[[#This Row],[New_Followers]]-Engagement_Summary[[#This Row],[Unfollows]] -> 1047 | I2: =(Engagement_Summary[[#This Row],[Net new follower]]-H1)/H1 -> #VALUE! | J2: {=_xlfn._xlws.FILTER(Campaign_Metadata[Campaign_Name],(Engagement_Summary[[#This Row],[Week_Start_Date]]>=Campaign_Metadata[Start_Date])*(Engagement_Summary[[#This Row],[Week_Start_Date]]<=Campaign_Metadata[End_Date]),"No Campaign")} -> No Campaign
A3: 45446 | B3: Facebook | C3: 1312 | D3: 310 | E3: 42654 | F3: 4.98 | G3: 9566 | H3: =Engagement_Summary[[#This Row],[New_Followers]]-Engagement_Summary[[#This Row],[Unfollows]] -> 1002 | I3: =(Engagement_Summary[[#This Row],[Net new follower]]-H2)/H2 -> -0.042979943 | J3: {=_xlfn._xlws.FILTER(Campaign_Metadata[Campaign_Name],(Engagement_Summary[[#This Row],[Week_Start_Date]]>=Campaign_Metadata[Start_Date])*(Engagement_Summary[[#This Row],[Week_Start_Date]]<=Campaign_Metadata[End_Date]),"No Campaign")} -> No Campaign
A4: 45446 | B4: Twitter | C4: 584 | D4: 169 | E4: 146834 | F4: 8.31 | G4: 26752 | H4: =Engagement_Summary[[#This Row],[New_Followers]]-Engagement_Summary[[#This Row],[Unfollows]] -> 415 | I4: =(Engagement_Summary[[#This Row],[Net new follower]]-H3)/H3 -> -0.58582834 | J4: {=_xlfn._xlws.FILTER(Campaign_Metadata[Campaign_Name],(Engagement_Summary[[#This Row],[Week_Start_Date]]>=Campaign_Metadata[Start_Date])*(Engagement_Summary[[#This Row],[Week_Start_Date]]<=Campaign_Metadata[End_Date]),"No Campaign")} -> No Campaign
A5: 45446 | B5: YouTube | C5: 1535 | D5: 445 | E5: 395536 | F5: 4.11 | G5: 30671 | H5: =Engagement_Summary[[#This Row],[New_Followers]]-Engagement_Summary[[#This Row],[Unfollows]] -> 1090 | I5: =(Engagement_Summary[[#This Row],[Net new follower]]-H4)/H4 -> 1.626506 | J5: {=_xlfn._xlws.FILTER(Campaign_Metadata[Campaign_Name],(Engagement_Summary[[#This Row],[Week_Start_Date]]>=Campaign_Metadata[Start_Date])*(Engagement_Summary[[#This Row],[Week_Start_Date]]<=Campaign_Metadata[End_Date]),"No Campaign")} -> No Campaign
A6: 45453 | B6: Instagram | C6: 656 | D6: 139 | E6: 49157 | F6: 9.05 | G6: 9920 | H6: =Engagement_Summary[[#This Row],[New_Followers]]-Engagement_Summary[[#This Row],[Unfollows]] -> 517 | I6: =(Engagement_Summary[[#This Row],[Net new follower]]-H5)/H5 -> -0.52568807 | J6: {=_xlfn._xlws.FILTER(Campaign_Metadata[Campaign_Name],(Engagement_Summary[[#This Row],[Week_Start_Date]]>=Campaign_Metadata[Start_Date])*(Engagement_Summary[[#This Row],[Week_Start_Date]]<=Campaign_Metadata[End_Date]),"No Campaign")} -> No Campaign
A7: 45453 | B7: Facebook | C7: 1697 | D7: 414 | E7: 316555 | F7: 2.37 | G7: 7924 | H7: =Engagement_Summary[[#This Row],[New_Followers]]-Engagement_Summary[[#This Row],[Unfollows]] -> 1283 | I7: =(Engagement_Summary[[#This Row],[Net new follower]]-H6)/H6 -> 1.4816248 | J7: {=_xlfn._xlws.FILTER(Campaign_Metadata[Campaign_Name],(Engagement_Summary[[#This Row],[Week_Start_Date]]>=Campaign_Metadata[Start_Date])*(Engagement_Summary[[#This Row],[Week_Start_Date]]<=Campaign_Metadata[End_Date]),"No Campaign")} -> No Campaign
A8: 45453 | B8: Twitter | C8: 436 | D8: 250 | E8: 254347 | F8: 4.01 | G8: 8912 | H8: =Engagement_Summary[[#This Row],[New_Followers]]-Engagement_Summary[[#This Row],[Unfollows]] -> 186 | I8: =(Engagement_Summary[[#This Row],[Net new follower]]-H7)/H7 -> -0.85502728 | J8: {=_xlfn._xlws.FILTER(Campaign_Metadata[Campaign_Name],(Engagement_Summary[[#This Row],[Week_Start_Date]]>=Campaign_Metadata[Start_Date])*(Engagement_Summary[[#This Row],[Week_Start_Date]]<=Campaign_Metadata[End_Date]),"No Campaign")} -> No Campaign
A9: 45453 | B9: YouTube | C9: 1197 | D9: 203 | E9: 413878 | F9: 3.16 | G9: 21205 | H9: =Engagement_Summary[[#This Row],[New_Followers]]-Engagement_Summary[[#This Row],[Unfollows]] -> 994 | I9: =(Engagement_Summary[[#This Row],[Net new follower]]-H8)/H8 -> 4.344086 | J9: {=_xlfn._xlws.FILTER(Campaign_Metadata[Campaign_Name],(Engagement_Summary[[#This Row],[Week_Start_Date]]>=Campaign_Metadata[Start_Date])*(Engagement_Summary[[#This Row],[Week_Start_Date]]<=Campaign_Metadata[End_Date]),"No Campaign")} -> No Campaign
A10: 45460 | B10: Instagram | C10: 1048 | D10: 155 | E10: 456946 | F10: 2.46 | G10: 11329 | H10: =Engagement_Summary[[#This Row],[New_Followers]]-Engagement_Summary[[#This Row],[Unfollows]] -> 893 | I10: =(Engagement_Summary[[#This Row],[Net new follower]]-H9)/H9 -> -0.10160966 | J10: {=_xlfn._xlws.FILTER(Campaign_Metadata[Campaign_Name],(Engagement_Summary[[#This Row],[Week_Start_Date]]>=Campaign_Metadata[Start_Date])*(Engagement_Summary[[#This Row],[Week_Start_Date]]<=Campaign_Metadata[End_Date]),"No Campaign")} -> CybertruckLaunch
A11: 45460 | B11: Facebook | C11: 1753 | D11: 371 | E11: 169496 | F11: 8.11 | G11: 46670 | H11: =Engagement_Summary[[#This Row],[New_Followers]]-Engagement_Summary[[#This Row],[Unfollows]] -> 1382 | I11: =(Engagement_Summary[[#This Row],[Net new follower]]-H10)/H10 -> 0.54759239 | J11: {=_xlfn._xlws.FILTER(Campaign_Metadata[Campaign_Name],(Engagement_Summary[[#This Row],[Week_Start_Date]]>=Campaign_Metadata[Start_Date])*(Engagement_Summary[[#This Row],[Week_Start_Date]]<=Campaign_Metadata[End_Date]),"No Campaign")} -> CybertruckLaunch
A12: 45460 | B12: Twitter | C12: 1335 | D12: 40 | E12: 122732 | F12: 8.19 | G12: 22482 | H12: =Engagement_Summary[[#This Row],[New_Followers]]-Engagement_Summary[[#This Row],[Unfollows]] -> 1295 | I12: =(Engagement_Summary[[#This Row],[Net new follower]]-H11)/H11 -> -0.062952243 | J12: {=_xlfn._xlws.FILTER(Campaign_Metadata[Campaign_Name],(Engagement_Summary[[#This Row],[Week_Start_Date]]>=Campaign_Metadata[Start_Date])*(Engagement_Summary[[#This Row],[Week_Start_Date]]<=Campaign_Metadata[End_Date]),"No Campaign")} -> CybertruckLaunch
A13: 45460 | B13: YouTube | C13: 403 | D13: 66 | E13: 382851 | F13: 3.49 | G13: 24313 | H13: =Engagement_Summary[[#This Row],[New_Followers]]-Engagement_Summary[[#This Row],[Unfollows]] -> 337 | I13: =(Engagement_Summary[[#This Row],[Net new follower]]-H12)/H12 -> -0.73976834 | J13: {=_xlfn._xlws.FILTER(Campaign_Metadata[Campaign_Name],(Engagement_Summary[[#This Row],[Week_Start_Date]]>=Campaign_Metadata[Start_Date])*(Engagement_Summary[[#This Row],[Week_Start_Date]]<=Campaign_Metadata[End_Date]),"No Campaign")} -> CybertruckLaunch
... A201: 45789 | B201: YouTube | C201: 119 | D201: 456 | E201: 82558 | F201: 6.81 | G201: 12174 | H201: =Engagement_Summary[[#This Row],[New_Followers]]-Engagement_Summary[[#This Row],[Unfollows]] -> -337 | I201: =(Engagement_Summary[[#This Row],[Net new follower]]-H200)/H200 -> -2.2527881 | J201: {=_xlfn._xlws.FILTER(Campaign_Metadata[Campaign_Name],(Engagement_Summary[[#This Row],[Week_Start_Date]]>=Campaign_Metadata[Start_Date])*(Engagement_Summary[[#This Row],[Week_Start_Date]]<=Campaign_Metadata[End_Date]),"No Campaign")} -> No Campaign

Sheet Task 1
A1: Post ID | B1: Platform | C1: Date | D1: Content Type | E1: Post Text | F1: Likes | G1: Shares | H1: Comments | I1: Impressions | J1: Reach | K1: Clicks | L1: Hashtags Used | M1: Campaign_Name
A2: P001 | B2: Twitter | C2: 45649 | D2: Reel | E2: Check out our latest reel on twitter! | F2: 1461 | G2: 184 | H2: 344 | I2: 21915 | J2: 21675 | K2: 15 | L2: #FutureOfDriving | M2: CybertruckLaunch
A3: P001 | B3: Twitter | C3: 45649 | D3: Reel | E3: Check out our latest reel on twitter! | F3: 1461 | G3: 184 | H3: 344 | I3: 21915 | J3: 21675 | K3: 15 | L3: #AnytimeIsTeslaTime | M3: CybertruckLaunch
A4: P002 | B4: Twitter | C4: 45750 | D4: Text | E4: Check out our latest text on twitter! | F4: 4054 | G4: 389 | H4: 493 | I4: 64864 | J4: 64383 | K4: 117 | L4: #TeslaCoInnovation | M4: ModelYCampaign
A5: P002 | B5: Twitter | C5: 45750 | D5: Text | E5: Check out our latest text on twitter! | F5: 4054 | G5: 389 | H5: 493 | I5: 64864 | J5: 64383 | K5: 117 | L5: #BetterWithTesla | M5: ModelYCampaign
A6: P003 | B6: YouTube | C6: 45789 | D6: Reel | E6: Check out our latest reel on youtube! | F6: 2795 | G6: 105 | H6: 49 | I6: 53105 | J6: 52307 | K6: 204 | L6: #TeslaCoInnovation | M6: FSDUpdate
A7: P004 | B7: Instagram | C7: 45516 | D7: Story | E7: Check out our latest story on instagram! | F7: 2404 | G7: 363 | H7: 138 | I7: 19232 | J7: 18636 | K7: 128 | L7: #EVRevolution | M7: SustainabilityDrive
A8: P005 | B8: YouTube | C8: 45469 | D8: Reel | E8: Check out our latest reel on youtube! | F8: 3557 | G8: 687 | H8: 424 | I8: 71140 | J8: 70701 | K8: 224 | L8: #EVRevolution | M8: CybertruckLaunch
A9: P005 | B9: YouTube | C9: 45469 | D9: Reel | E9: Check out our latest reel on youtube! | F9: 3557 | G9: 687 | H9: 424 | I9: 71140 | J9: 70701 | K9: 224 | L9: #TeslaCoInnovation | M9: CybertruckLaunch
A10: P006 | B10: Facebook | C10: 45596 | D10: Carousel | E10: Check out our latest carousel on facebook! | F10: 2945 | G10: 930 | H10: 355 | I10: 23560 | J10: 23275 | K10: 256 | L10: #TeslaCoInnovation | M10: ModelYCampaign
A11: P007 | B11: Twitter | C11: 45467 | D11: Carousel | E11: Check out our latest carousel on twitter! | F11: 3860 | G11: 201 | H11: 279 | I11: 61760 | J11: 61660 | K11: 235 | L11: #TeslaCoInnovation | M11: ModelYCampaign
A12: P008 | B12: YouTube | C12: 45486 | D12: Image | E12: Check out our latest image on youtube! | F12: 3929 | G12: 262 | H12: 278 | I12: 43219 | J12: 42841 | K12: 39 | L12: #EVRevolution | M12: SustainabilityDrive
A13: P009 | B13: Facebook | C13: 45534 | D13: Text | E13: Check out our latest text on facebook! | F13: 3784 | G13: 808 | H13: 404 | I13: 56760 | J13: 56343 | K13: 131 | L13: #TeslaCoInnovation | M13: ModelYCampaign
... A17: P013 | B17: YouTube | C17: 45614 | D17: Carousel | E17: Check out our latest carousel on youtube! | F17: 1171 | G17: 286 | H17: 231 | I17: 22249 | J17: 21282 | K17: 114 | L17: #EVRevolution | M17: CybertruckLaunch
A18: P014 | B18: Facebook | C18: 45704 | D18: Story | E18: Check out our latest story on facebook! | F18: 4242 | G18: 555 | H18: 131 | I18: 33936 | J18: 33802 | K18: 265 | L18: #FutureOfDriving
A19: P015 | B19: Facebook | C19: 45589 | D19: Video | E19: Check out our latest video on facebook! | F19: 3888 | G19: 604 | H19: 128 | I19: 77760 | J19: 77167 | K19: 20 | L19: #FutureOfDriving | M19: CybertruckLaunch
A20: P016 | B20: Facebook | C20: 45530 | D20: Text | E20: Check out our latest text on facebook! | F20: 3452 | G20: 377 | H20: 360 | I20: 55232 | J20: 55075 | K20: 87 | L20: #FutureOfDriving | M20: FSDUpdate
A21: P017 | B21: Facebook | C21: 45782 | D21: Text | E21: Check out our latest text on facebook! | F21: 4441 | G21: 511 | H21: 70 | I21: 53292 | J21: 53082 | K21: 159 | L21: #EVRevolution | M21: SustainabilityDrive
A22: P018 | B22: Instagram | C22: 45523 | D22: Reel | E22: Check out our latest reel on instagram! | F22: 3000 | G22: 382 | H22: 325 | I22: 36000 | J22: 35819 | K22: 19 | L22: #FutureOfDriving | M22: CybertruckLaunch
A23: P019 | B23: Instagram | C23: 45466 | D23: Video | E23: Check out our latest video on instagram! | F23: 1071 | G23: 519 | H23: 22 | I23: 16065 | J23: 15865 | K23: 103 | L23: #TeslaCoInnovation | M23: SustainabilityDrive
A24: P020 | B24: Instagram | C24: 45544 | D24: Carousel | E24: Check out our latest carousel on instagram! | F24: 4054 | G24: 488 | H24: 373 | I24: 77026 | J24: 76881 | K24: 25 | L24: #TeslaCoInnovation | M24: CybertruckLaunch
A25: P021 | B25: Instagram | C25: 45661 | D25: Reel | E25: Check out our latest reel on instagram! | F25: 4838 | G25: 640 | H25: 128 | I25: 72570 | J25: 72396 | K25: 83 | L25: #FutureOfDriving | M25: SustainabilityDrive
A26: P022 | B26: Facebook | C26: 45715 | D26: Text | E26: Check out our latest text on facebook! | F26: 1570 | G26: 187 | H26: 260 | I26: 25120 | J26: 24613 | K26: 133 | L26: #TeslaCoInnovation | M26: SustainabilityDrive
A27: P023 | B27: Facebook | C27: 45602 | D27: Video | E27: Check out our latest video on facebook! | F27: 1606 | G27: 547 | H27: 316 | I27: 32120 | J27: 31736 | K27: 225 | L27: #TeslaCoInnovation | M27: ModelYCampaign
A28: P023 | B28: Facebook | C28: 45602 | D28: Video | E28: Check out our latest video on facebook! | F28: 1606 | G28: 547 | H28: 316 | I28: 32120 | J28: 31736 | K28: 225 | L28: #AnytimeIsTeslaTime | M28: ModelYCampaign
A29: P024 | B29: Facebook | C29: 45680 | D29: Video | E29: Check out our latest video on facebook! | F29: 3961 | G29: 761 | H29: 131 | I29: 67337 | J29: 66615 | K29: 161 | L29: #FutureOfDriving | M29: FSDUpdate
A30: P025 | B30: Twitter | C30: 45757 | D30: Carousel | E30: Check out our latest carousel on twitter! | F30: 3128 | G30: 211 | H30: 197 | I30: 59432 | J30: 59182 | K30: 238 | L30: #EVRevolution
A31: P026 | B31: YouTube | C31: 45752 | D31: Reel | E31: Check out our latest reel on youtube! | F31: 3009 | G31: 413 | H31: 358 | I31: 42126 | J31: 41309 | K31: 211 | L31: #FutureOfDriving | M31: ModelYCampaign
A32: P027 | B32: YouTube | C32: 45552 | D32: Text | E32: Check out our latest text on youtube! | F32: 2076 | G32: 195 | H32: 104 | I32: 33216 | J32: 32244 | K32: 51 | L32: #FutureOfDriving | M32: SustainabilityDrive
A33: P028 | B33: Instagram | C33: 45720 | D33: Video | E33: Check out our latest video on instagram! | F33: 432 | G33: 624 | H33: 123 | I33: 6912 | J33: 6259 | K33: 79 | L33: #FutureOfDriving | M33: SustainabilityDrive
A34: P029 | B34: Instagram | C34: 45688 | D34: Carousel | E34: Check out our latest carousel on instagram! | F34: 2566 | G34: 118 | H34: 37 | I34: 12830 | J34: 12264 | K34: 221 | L34: #FutureOfDriving | M34: FSDUpdate
A35: P030 | B35: Instagram | C35: 45713 | D35: Video | E35: Check out our latest video on instagram! | F35: 3095 | G35: 39 | H35: 78 | I35: 55710 | J35: 54808 | K35: 93 | L35: #EVRevolution
A36: P031 | B36: Instagram | C36: 45642 | D36: Text | E36: Check out our latest text on instagram! | F36: 438 | G36: 153 | H36: 275 | I36: 3066 | J36: 2701 | K36: 282 | L36: #TeslaCoInnovation | M36: ModelYCampaign
A37: P032 | B37: Twitter | C37: 45504 | D37: Carousel | E37: Check out our latest carousel on twitter! | F37: 2278 | G37: 10 | H37: 321 | I37: 13668 | J37: 12676 | K37: 275 | L37: #EVRevolution | M37: CybertruckLaunch
A38: P033 | B38: Facebook | C38: 45525 | D38: Image | E38: Check out our latest image on facebook! | F38: 1407 | G38: 400 | H38: 351 | I38: 16884 | J38: 15954 | K38: 113 | L38: #TeslaCoInnovation | M38: CybertruckLaunch
A39: P034 | B39: Facebook | C39: 45742 | D39: Text | E39: Check out our latest text on facebook! | F39: 1652 | G39: 89 | H39: 357 | I39: 29736 | J39: 28771 | K39: 215 | L39: #TeslaCoInnovation | M39: FSDUpdate
A40: P035 | B40: Instagram | C40: 45626 | D40: Video | E40: Check out our latest video on instagram! | F40: 3775 | G40: 16 | H40: 239 | I40: 33975 | J40: 33310 | K40: 271 | L40: #FutureOfDriving | M40: ModelYCampaign
A41: P036 | B41: Instagram | C41: 45766 | D41: Story | E41: Check out our latest story on instagram! | F41: 4518 | G41: 285 | H41: 383 | I41: 67770 | J41: 67621 | K41: 31 | L41: #EVRevolution | M41: ModelYCampaign
A42: P037 | B42: Facebook | C42: 45663 | D42: Carousel | E42: Check out our latest carousel on facebook! | F42: 3024 | G42: 925 | H42: 350 | I42: 24192 | J42: 23518 | K42: 36 | L42: #EVRevolution | M42: ModelYCampaign
A43: P038 | B43: YouTube | C43: 45705 | D43: Reel | E43: Check out our latest reel on youtube! | F43: 3138 | G43: 123 | H43: 291 | I43: 28242 | J43: 27550 | K43: 87 | L43: #TeslaCoInnovation | M43: SustainabilityDrive
...

Sheet Task 2.1
A1: Post ID | B1: Platform | C1: Date | D1: Content Type | E1: Post Text | F1: Likes | G1: Shares | H1: Comments | I1: Impressions | J1: Reach | K1: Clicks | L1: Hashtags Used | M1: Campaign_Name | N1: Engagement Rate
A2: P001 | B2: Twitter | C2: 45649 | D2: Reel | E2: Check out our latest reel on twitter! | F2: 1461 | G2: 184 | H2: 344 | I2: 21915 | J2: 21675 | K2: 15 | L2: #FutureOfDriving | M2: CybertruckLaunch | N2: =(Posts11[[#This Row],[Likes]]+Posts11[[#This Row],[Shares]]+Posts11[[#This Row],[Comments]])/Posts11[[#This Row],[Impressions]] -> 0.090759754
A3: P001 | B3: Twitter | C3: 45649 | D3: Reel | E3: Check out our latest reel on twitter! | F3: 1461 | G3: 184 | H3: 344 | I3: 21915 | J3: 21675 | K3: 15 | L3: #AnytimeIsTeslaTime | M3: CybertruckLaunch | N3: =(Posts11[[#This Row],[Likes]]+Posts11[[#This Row],[Shares]]+Posts11[[#This Row],[Comments]])/Posts11[[#This Row],[Impressions]] -> 0.090759754
A4: P002 | B4: Twitter | C4: 45750 | D4: Text | E4: Check out our latest text on twitter! | F4: 4054 | G4: 389 | H4: 493 | I4: 64864 | J4: 64383 | K4: 117 | L4: #TeslaCoInnovation | M4: ModelYCampaign | N4: =(Posts11[[#This Row],[Likes]]+Posts11[[#This Row],[Shares]]+Posts11[[#This Row],[Comments]])/Posts11[[#This Row],[Impressions]] -> 0.076097681
A5: P002 | B5: Twitter | C5: 45750 | D5: Text | E5: Check out our latest text on twitter! | F5: 4054 | G5: 389 | H5: 493 | I5: 64864 | J5: 64383 | K5: 117 | L5: #BetterWithTesla | M5: ModelYCampaign | N5: =(Posts11[[#This Row],[Likes]]+Posts11[[#This Row],[Shares]]+Posts11[[#This Row],[Comments]])/Posts11[[#This Row],[Impressions]] -> 0.076097681
A6: P003 | B6: YouTube | C6: 45789 | D6: Reel | E6: Check out our latest reel on youtube! | F6: 2795 | G6: 105 | H6: 49 | I6: 53105 | J6: 52307 | K6: 204 | L6: #TeslaCoInnovation | M6: FSDUpdate | N6: =(Posts11[[#This Row],[Likes]]+Posts11[[#This Row],[Shares]]+Posts11[[#This Row],[Comments]])/Posts11[[#This Row],[Impressions]] -> 0.055531494
A7: P004 | B7: Instagram | C7: 45516 | D7: Story | E7: Check out our latest story on instagram! | F7: 2404 | G7: 363 | H7: 138 | I7: 19232 | J7: 18636 | K7: 128 | L7: #EVRevolution | M7: SustainabilityDrive | N7: =(Posts11[[#This Row],[Likes]]+Posts11[[#This Row],[Shares]]+Posts11[[#This Row],[Comments]])/Posts11[[#This Row],[Impressions]] -> 0.15105033
A8: P005 | B8: YouTube | C8: 45469 | D8: Reel | E8: Check out our latest reel on youtube! | F8: 3557 | G8: 687 | H8: 424 | I8: 71140 | J8: 70701 | K8: 224 | L8: #EVRevolution | M8: CybertruckLaunch | N8: =(Posts11[[#This Row],[Likes]]+Posts11[[#This Row],[Shares]]+Posts11[[#This Row],[Comments]])/Posts11[[#This Row],[Impressions]] -> 0.065617093
A9: P005 | B9: YouTube | C9: 45469 | D9: Reel | E9: Check out our latest reel on youtube! | F9: 3557 | G9: 687 | H9: 424 | I9: 71140 | J9: 70701 | K9: 224 | L9: #TeslaCoInnovation | M9: CybertruckLaunch | N9: =(Posts11[[#This Row],[Likes]]+Posts11[[#This Row],[Shares]]+Posts11[[#This Row],[Comments]])/Posts11[[#This Row],[Impressions]] -> 0.065617093
A10: P006 | B10: Facebook | C10: 45596 | D10: Carousel | E10: Check out our latest carousel on facebook! | F10: 2945 | G10: 930 | H10: 355 | I10: 23560 | J10: 23275 | K10: 256 | L10: #TeslaCoInnovation | M10: ModelYCampaign | N10: =(Posts11[[#This Row],[Likes]]+Posts11[[#This Row],[Shares]]+Posts11[[#This Row],[Comments]])/Posts11[[#This Row],[Impressions]] -> 0.1795416 | Q10: Platform | R10: Avg Engagement rate
A11: P007 | B11: Twitter | C11: 45467 | D11: Carousel | E11: Check out our latest carousel on twitter! | F11: 3860 | G11: 201 | H11: 279 | I11: 61760 | J11: 61660 | K11: 235 | L11: #TeslaCoInnovation | M11: ModelYCampaign | N11: =(Posts11[[#This Row],[Likes]]+Posts11[[#This Row],[Shares]]+Posts11[[#This Row],[Comments]])/Posts11[[#This Row],[Impressions]] -> 0.070272021 | Q11: Twitter | R11: =AVERAGEIF(Posts[Platform],Q11,Posts11[Engagement Rate]) -> 0.13739369
A12: P008 | B12: YouTube | C12: 45486 | D12: Image | E12: Check out our latest image on youtube! | F12: 3929 | G12: 262 | H12: 278 | I12: 43219 | J12: 42841 | K12: 39 | L12: #EVRevolution | M12: SustainabilityDrive | N12: =(Posts11[[#This Row],[Likes]]+Posts11[[#This Row],[Shares]]+Posts11[[#This Row],[Comments]])/Posts11[[#This Row],[Impressions]] -> 0.1034036 | Q12: YouTube | R12: =AVERAGEIF(Posts[Platform],Q12,Posts11[Engagement Rate]) -> 0.13298735
A13: P009 | B13: Facebook | C13: 45534 | D13: Text | E13: Check out our latest text on facebook! | F13: 3784 | G13: 808 | H13: 404 | I13: 56760 | J13: 56343 | K13: 131 | L13: #TeslaCoInnovation | M13: ModelYCampaign | N13: =(Posts11[[#This Row],[Likes]]+Posts11[[#This Row],[Shares]]+Posts11[[#This Row],[Comments]])/Posts11[[#This Row],[Impressions]] -> 0.088019732 | Q13: Instagram | R13: =AVERAGEIF(Posts[Platform],Q13,Posts11[Engagement Rate]) -> 0.18531785
A14: P010 | B14: Facebook | C14: 45727 | D14: Image | E14: Check out our latest image on facebook! | F14: 4241 | G14: 902 | H14: 47 | I14: 72097 | J14: 71598 | K14: 167 | L14: #TeslaCoInnovation | M14: ModelYCampaign | N14: =(Posts11[[#This Row],[Likes]]+Posts11[[#This Row],[Shares]]+Posts11[[#This Row],[Comments]])/Posts11[[#This Row],[Impressions]] -> 0.071986352 | Q14: Facebook | R14: =AVERAGEIF(Posts[Platform],Q14,Posts11[Engagement Rate]) -> 0.12094203
A15: P011 | B15: Instagram | C15: 45690 | D15: Story | E15: Check out our latest story on instagram! | F15: 1792 | G15: 614 | H15: 497 | I15: 25088 | J15: 24675 | K15: 65 | L15: #FutureOfDriving | M15: SustainabilityDrive | N15: =(Posts11[[#This Row],[Likes]]+Posts11[[#This Row],[Shares]]+Posts11[[#This Row],[Comments]])/Posts11[[#This Row],[Impressions]] -> 0.11571269
A16: P012 | B16: Facebook | C16: 45494 | D16: Reel | E16: Check out our latest reel on facebook! | F16: 1946 | G16: 686 | H16: 377 | I16: 23352 | J16: 22982 | K16: 213 | L16: #FutureOfDriving | M16: FSDUpdate | N16: =(Posts11[[#This Row],[Likes]]+Posts11[[#This Row],[Shares]]+Posts11[[#This Row],[Comments]])/Posts11[[#This Row],[Impressions]] -> 0.12885406
A17: P013 | B17: YouTube | C17: 45614 | D17: Carousel | E17: Check out our latest carousel on youtube! | F17: 1171 | G17: 286 | H17: 231 | I17: 22249 | J17: 21282 | K17: 114 | L17: #EVRevolution | M17: CybertruckLaunch | N17: =(Posts11[[#This Row],[Likes]]+Posts11[[#This Row],[Shares]]+Posts11[[#This Row],[Comments]])/Posts11[[#This Row],[Impressions]] -> 0.075868578
A18: P014 | B18: Facebook | C18: 45704 | D18: Story | E18: Check out our latest story on facebook! | F18: 4242 | G18: 555 | H18: 131 | I18: 33936 | J18: 33802 | K18: 265 | L18: #FutureOfDriving | N18: =(Posts11[[#This Row],[Likes]]+Posts11[[#This Row],[Shares]]+Posts11[[#This Row],[Comments]])/Posts11[[#This Row],[Impressions]] -> 0.14521452
A19: P015 | B19: Facebook | C19: 45589 | D19: Video | E19: Check out our latest video on facebook! | F19: 3888 | G19: 604 | H19: 128 | I19: 77760 | J19: 77167 | K19: 20 | L19: #FutureOfDriving | M19: CybertruckLaunch | N19: =(Posts11[[#This Row],[Likes]]+Posts11[[#This Row],[Shares]]+Posts11[[#This Row],[Comments]])/Posts11[[#This Row],[Impressions]] -> 0.05941358
A20: P016 | B20: Facebook | C20: 45530 | D20: Text | E20: Check out our latest text on facebook! | F20: 3452 | G20: 377 | H20: 360 | I20: 55232 | J20: 55075 | K20: 87 | L20: #FutureOfDriving | M20: FSDUpdate | N20: =(Posts11[[#This Row],[Likes]]+Posts11[[#This Row],[Shares]]+Posts11[[#This Row],[Comments]])/Posts11[[#This Row],[Impressions]] -> 0.075843714
A21: P017 | B21: Facebook | C21: 45782 | D21: Text | E21: Check out our latest text on facebook! | F21: 4441 | G21: 511 | H21: 70 | I21: 53292 | J21: 53082 | K21: 159 | L21: #EVRevolution | M21: SustainabilityDrive | N21: =(Posts11[[#This Row],[Likes]]+Posts11[[#This Row],[Shares]]+Posts11[[#This Row],[Comments]])/Posts11[[#This Row],[Impressions]] -> 0.094235533
A22: P018 | B22: Instagram | C22: 45523 | D22: Reel | E22: Check out our latest reel on instagram! | F22: 3000 | G22: 382 | H22: 325 | I22: 36000 | J22: 35819 | K22: 19 | L22: #FutureOfDriving | M22: CybertruckLaunch | N22: =(Posts11[[#This Row],[Likes]]+Posts11[[#This Row],[Shares]]+Posts11[[#This Row],[Comments]])/Posts11[[#This Row],[Impressions]] -> 0.10297222
A23: P019 | B23: Instagram | C23: 45466 | D23: Video | E23: Check out our latest video on instagram! | F23: 1071 | G23: 519 | H23: 22 | I23: 16065 | J23: 15865 | K23: 103 | L23: #TeslaCoInnovation | M23: SustainabilityDrive | N23: =(Posts11[[#This Row],[Likes]]+Posts11[[#This Row],[Shares]]+Posts11[[#This Row],[Comments]])/Posts11[[#This Row],[Impressions]] -> 0.10034236
A24: P020 | B24: Instagram | C24: 45544 | D24: Carousel | E24: Check out our latest carousel on instagram! | F24: 4054 | G24: 488 | H24: 373 | I24: 77026 | J24: 76881 | K24: 25 | L24: #TeslaCoInnovation | M24: CybertruckLaunch | N24: =(Posts11[[#This Row],[Likes]]+Posts11[[#This Row],[Shares]]+Posts11[[#This Row],[Comments]])/Posts11[[#This Row],[Impressions]] -> 0.063809623
A25: P021 | B25: Instagram | C25: 45661 | D25: Reel | E25: Check out our latest reel on instagram! | F25: 4838 | G25: 640 | H25: 128 | I25: 72570 | J25: 72396 | K25: 83 | L25: #FutureOfDriving | M25: SustainabilityDrive | N25: =(Posts11[[#This Row],[Likes]]+Posts11[[#This Row],[Shares]]+Posts11[[#This Row],[Comments]])/Posts11[[#This Row],[Impressions]] -> 0.077249552
A26: P022 | B26: Facebook | C26: 45715 | D26: Text | E26: Check out our latest text on facebook! | F26: 1570 | G26: 187 | H26: 260 | I26: 25120 | J26: 24613 | K26: 133 | L26: #TeslaCoInnovation | M26: SustainabilityDrive | N26: =(Posts11[[#This Row],[Likes]]+Posts11[[#This Row],[Shares]]+Posts11[[#This Row],[Comments]])/Posts11[[#This Row],[Impressions]] -> 0.080294586
A27: P023 | B27: Facebook | C27: 45602 | D27: Video | E27: Check out our latest video on facebook! | F27: 1606 | G27: 547 | H27: 316 | I27: 32120 | J27: 31736 | K27: 225 | L27: #TeslaCoInnovation | M27: ModelYCampaign | N27: =(Posts11[[#This Row],[Likes]]+Posts11[[#This Row],[Shares]]+Posts11[[#This Row],[Comments]])/Posts11[[#This Row],[Impressions]] -> 0.076867995
A28: P023 | B28: Facebook | C28: 45602 | D28: Video | E28: Check out our latest video on facebook! | F28: 1606 | G28: 547 | H28: 316 | I28: 32120 | J28: 31736 | K28: 225 | L28: #AnytimeIsTeslaTime | M28: ModelYCampaign | N28: =(Posts11[[#This Row],[Likes]]+Posts11[[#This Row],[Shares]]+Posts11[[#This Row],[Comments]])/Posts11[[#This Row],[Impressions]] -> 0.076867995
A29: P024 | B29: Facebook | C29: 45680 | D29: Video | E29: Check out our latest video on facebook! | F29: 3961 | G29: 761 | H29: 131 | I29: 67337 | J29: 66615 | K29: 161 | L29: #FutureOfDriving | M29: FSDUpdate | N29: =(Posts11[[#This Row],[Likes]]+Posts11[[#This Row],[Shares]]+Posts11[[#This Row],[Comments]])/Posts11[[#This Row],[Impressions]] -> 0.072070333
A30: P025 | B30: Twitter | C30: 45757 | D30: Carousel | E30: Check out our latest carousel on twitter! | F30: 3128 | G30: 211 | H30: 197 | I30: 59432 | J30: 59182 | K30: 238 | L30: #EVRevolution | N30: =(Posts11[[#This Row],[Likes]]+Posts11[[#This Row],[Shares]]+Posts11[[#This Row],[Comments]])/Posts11[[#This Row],[Impressions]] -> 0.059496568
A31: P026 | B31: YouTube | C31: 45752 | D31: Reel | E31: Check out our latest reel on youtube! | F31: 3009 | G31: 413 | H31: 358 | I31: 42126 | J31: 41309 | K31: 211 | L31: #FutureOfDriving | M31: ModelYCampaign | N31: =(Posts11[[#This Row],[Likes]]+Posts11[[#This Row],[Shares]]+Posts11[[#This Row],[Comments]])/Posts11[[#This Row],[Impressions]] -> 0.089730808
A32: P027 | B32: YouTube | C32: 45552 | D32: Text | E32: Check out our latest text on youtube! | F32: 2076 | G32: 195 | H32: 104 | I32: 33216 | J32: 32244 | K32: 51 | L32: #FutureOfDriving | M32: SustainabilityDrive | N32: =(Posts11[[#This Row],[Likes]]+Posts11[[#This Row],[Shares]]+Posts11[[#This Row],[Comments]])/Posts11[[#This Row],[Impressions]] -> 0.071501686
A33: P028 | B33: Instagram | C33: 45720 | D33: Video | E33: Check out our latest video on instagram! | F33: 432 | G33: 624 | H33: 123 | I33: 6912 | J33: 6259 | K33: 79 | L33: #FutureOfDriving | M33: SustainabilityDrive | N33: =(Posts11[[#This Row],[Likes]]+Posts11[[#This Row],[Shares]]+Posts11[[#This Row],[Comments]])/Posts11[[#This Row],[Impressions]] -> 0.17057292
A34: P029 | B34: Instagram | C34: 45688 | D34: Carousel | E34: Check out our latest carousel on instagram! | F34: 2566 | G34: 118 | H34: 37 | I34: 12830 | J34: 12264 | K34: 221 | L34: #FutureOfDriving | M34: FSDUpdate | N34: =(Posts11[[#This Row],[Likes]]+Posts11[[#This Row],[Shares]]+Posts11[[#This Row],[Comments]])/Posts11[[#This Row],[Impressions]] -> 0.21208106
A35: P030 | B35: Instagram | C35: 45713 | D35: Video | E35: Check out our latest video on instagram! | F35: 3095 | G35: 39 | H35: 78 | I35: 55710 | J35: 54808 | K35: 93 | L35: #EVRevolution | N35: =(Posts11[[#This Row],[Likes]]+Posts11[[#This Row],[Shares]]+Posts11[[#This Row],[Comments]])/Posts11[[#This Row],[Impressions]] -> 0.057655717
A36: P031 | B36: Instagram | C36: 45642 | D36: Text | E36: Check out our latest text on instagram! | F36: 438 | G36: 153 | H36: 275 | I36: 3066 | J36: 2701 | K36: 282 | L36: #TeslaCoInnovation | M36: ModelYCampaign | N36: =(Posts11[[#This Row],[Likes]]+Posts11[[#This Row],[Shares]]+Posts11[[#This Row],[Comments]])/Posts11[[#This Row],[Impressions]] -> 0.28245271
A37: P032 | B37: Twitter | C37: 45504 | D37: Carousel | E37: Check out our latest carousel on twitter! | F37: 2278 | G37: 10 | H37: 321 | I37: 13668 | J37: 12676 | K37: 275 | L37: #EVRevolution | M37: CybertruckLaunch | N37: =(Posts11[[#This Row],[Likes]]+Posts11[[#This Row],[Shares]]+Posts11[[#This Row],[Comments]])/Posts11[[#This Row],[Impressions]] -> 0.19088382
A38: P033 | B38: Facebook | C38: 45525 | D38: Image | E38: Check out our latest image on facebook! | F38: 1407 | G38: 400 | H38: 351 | I38: 16884 | J38: 15954 | K38: 113 | L38: #TeslaCoInnovation | M38: CybertruckLaunch | N38: =(Posts11[[#This Row],[Likes]]+Posts11[[#This Row],[Shares]]+Posts11[[#This Row],[Comments]])/Posts11[[#This Row],[Impressions]] -> 0.12781331
A39: P034 | B39: Facebook | C39: 45742 | D39: Text | E39: Check out our latest text on facebook! | F39: 1652 | G39: 89 | H39: 357 | I39: 29736 | J39: 28771 | K39: 215 | L39: #TeslaCoInnovation | M39: FSDUpdate | N39: =(Posts11[[#This Row],[Likes]]+Posts11[[#This Row],[Shares]]+Posts11[[#This Row],[Comments]])/Posts11[[#This Row],[Impressions]] -> 0.07055421
A40: P035 | B40: Instagram | C40: 45626 | D40: Video | E40: Check out our latest video on instagram! | F40: 3775 | G40: 16 | H40: 239 | I40: 33975 | J40: 33310 | K40: 271 | L40: #FutureOfDriving | M40: ModelYCampaign | N40: =(Posts11[[#This Row],[Likes]]+Posts11[[#This Row],[Shares]]+Posts11[[#This Row],[Comments]])/Posts11[[#This Row],[Impressions]] -> 0.11861663
...

Sheet Task 2.2
A1: Post ID | B1: Platform | C1: Date | D1: Content Type | E1: Post Text | F1: Likes | G1: Shares | H1: Comments | I1: Impressions | J1: Reach | K1: Clicks | L1: Hashtags Used | M1: Campaign_Name | N1: Engagement Rate
A2: P220 | B2: Instagram | C2: 45445 | D2: Story | E2: Check out our latest story on instagram! | F2: 84 | G2: 897 | H2: 85 | I2: 588 | J2: 8 | K2: 12 | L2: #EVRevolution | N2: =(Posts1114[[#This Row],[Likes]]+Posts1114[[#This Row],[Shares]]+Posts1114[[#This Row],[Comments]])/Posts1114[[#This Row],[Impressions]] -> 1.8129252
A3: P058 | B3: Instagram | C3: 45762 | D3: Reel | E3: Check out our latest reel on instagram! | F3: 103 | G3: 770 | H3: 19 | I3: 1030 | J3: 410 | K3: 262 | L3: #TeslaCoInnovation | M3: SustainabilityDrive | N3: =(Posts1114[[#This Row],[Likes]]+Posts1114[[#This Row],[Shares]]+Posts1114[[#This Row],[Comments]])/Posts1114[[#This Row],[Impressions]] -> 0.86601942
A4: P232 | B4: Twitter | C4: 45776 | D4: Story | E4: Check out our latest story on twitter! | F4: 249 | G4: 592 | H4: 230 | I4: 1494 | J4: 1044 | K4: 201 | L4: #EVRevolution | M4: SustainabilityDrive | N4: =(Posts1114[[#This Row],[Likes]]+Posts1114[[#This Row],[Shares]]+Posts1114[[#This Row],[Comments]])/Posts1114[[#This Row],[Impressions]] -> 0.71686747
A5: P178 | B5: Instagram | C5: 45603 | D5: Video | E5: Check out our latest video on instagram! | F5: 129 | G5: 643 | H5: 136 | I5: 1290 | J5: 839 | K5: 238 | L5: #TeslaCoInnovation | M5: SustainabilityDrive | N5: =(Posts1114[[#This Row],[Likes]]+Posts1114[[#This Row],[Shares]]+Posts1114[[#This Row],[Comments]])/Posts1114[[#This Row],[Impressions]] -> 0.70387597
A6: P175 | B6: Instagram | C6: 45674 | D6: Reel | E6: Check out our latest reel on instagram! | F6: 142 | G6: 784 | H6: 183 | I6: 1704 | J6: 995 | K6: 154 | L6: #FutureOfDriving | M6: SustainabilityDrive | N6: =(Posts1114[[#This Row],[Likes]]+Posts1114[[#This Row],[Shares]]+Posts1114[[#This Row],[Comments]])/Posts1114[[#This Row],[Impressions]] -> 0.6508216
A7: P062 | B7: Twitter | C7: 45618 | D7: Carousel | E7: Check out our latest carousel on twitter! | F7: 53 | G7: 81 | H7: 379 | I7: 954 | J7: 7 | K7: 148 | L7: #TeslaCoInnovation | M7: FSDUpdate | N7: =(Posts1114[[#This Row],[Likes]]+Posts1114[[#This Row],[Shares]]+Posts1114[[#This Row],[Comments]])/Posts1114[[#This Row],[Impressions]] -> 0.53773585
A8: P264 | B8: Twitter | C8: 45687 | D8: Image | E8: Check out our latest image on twitter! | F8: 59 | G8: 163 | H8: 93 | I8: 590 | J8: 475 | K8: 293 | L8: #TeslaCoInnovation | M8: ModelYCampaign | N8: =(Posts1114[[#This Row],[Likes]]+Posts1114[[#This Row],[Shares]]+Posts1114[[#This Row],[Comments]])/Posts1114[[#This Row],[Impressions]] -> 0.53389831
A9: P143 | B9: YouTube | C9: 45567 | D9: Carousel | E9: Check out our latest carousel on youtube! | F9: 80 | G9: 362 | H9: 80 | I9: 1040 | J9: 349 | K9: 117 | L9: #TeslaCoInnovation | M9: FSDUpdate | N9: =(Posts1114[[#This Row],[Likes]]+Posts1114[[#This Row],[Shares]]+Posts1114[[#This Row],[Comments]])/Posts1114[[#This Row],[Impressions]] -> 0.50192308
A10: P210 | B10: YouTube | C10: 45707 | D10: Image | E10: Check out our latest image on youtube! | F10: 257 | G10: 966 | H10: 398 | I10: 3341 | J10: 2753 | K10: 287 | L10: #FutureOfDriving | M10: CybertruckLaunch | N10: =(Posts1114[[#This Row],[Likes]]+Posts1114[[#This Row],[Shares]]+Posts1114[[#This Row],[Comments]])/Posts1114[[#This Row],[Impressions]] -> 0.48518408
A11: P070 | B11: Facebook | C11: 45749 | D11: Video | E11: Check out our latest video on facebook! | F11: 199 | G11: 772 | H11: 400 | I11: 3582 | J11: 2988 | K11: 43 | L11: #TeslaCoInnovation | N11: =(Posts1114[[#This Row],[Likes]]+Posts1114[[#This Row],[Shares]]+Posts1114[[#This Row],[Comments]])/Posts1114[[#This Row],[Impressions]] -> 0.38274707
A12: P214 | B12: Instagram | C12: 45649 | D12: Image | E12: Check out our latest image on instagram! | F12: 521 | G12: 746 | H12: 315 | I12: 4168 | J12: 3399 | K12: 282 | L12: #FutureOfDriving | M12: ModelYCampaign | N12: =(Posts1114[[#This Row],[Likes]]+Posts1114[[#This Row],[Shares]]+Posts1114[[#This Row],[Comments]])/Posts1114[[#This Row],[Impressions]] -> 0.37955854
A13: P053 | B13: YouTube | C13: 45712 | D13: Carousel | E13: Check out our latest carousel on youtube! | F13: 804 | G13: 639 | H13: 43 | I13: 4020 | J13: 3144 | K13: 11 | L13: #EVRevolution | N13: =(Posts1114[[#This Row],[Likes]]+Posts1114[[#This Row],[Shares]]+Posts1114[[#This Row],[Comments]])/Posts1114[[#This Row],[Impressions]] -> 0.36965174
A14: P053 | B14: YouTube | C14: 45712 | D14: Carousel | E14: Check out our latest carousel on youtube! | F14: 804 | G14: 639 | H14: 43 | I14: 4020 | J14: 3144 | K14: 11 | L14: #BetterWithTesla | N14: =(Posts1114[[#This Row],[Likes]]+Posts1114[[#This Row],[Shares]]+Posts1114[[#This Row],[Comments]])/Posts1114[[#This Row],[Impressions]] -> 0.36965174
A15: P102 | B15: Twitter | C15: 45553 | D15: Reel | E15: Check out our latest reel on twitter! | F15: 1000 | G15: 978 | H15: 162 | I15: 6000 | J15: 5221 | K15: 223 | L15: #EVRevolution | M15: ModelYCampaign | N15: =(Posts1114[[#This Row],[Likes]]+Posts1114[[#This Row],[Shares]]+Posts1114[[#This Row],[Comments]])/Posts1114[[#This Row],[Impressions]] -> 0.35666667
A16: P124 | B16: YouTube | C16: 45753 | D16: Carousel | E16: Check out our latest carousel on youtube! | F16: 736 | G16: 771 | H16: 225 | I16: 5152 | J16: 4706 | K16: 19 | L16: #EVRevolution | M16: CybertruckLaunch | N16: =(Posts1114[[#This Row],[Likes]]+Posts1114[[#This Row],[Shares]]+Posts1114[[#This Row],[Comments]])/Posts1114[[#This Row],[Impressions]] -> 0.33618012
A17: P121 | B17: Instagram | C17: 45502 | D17: Story | E17: Check out our latest story on instagram! | F17: 498 | G17: 701 | H17: 412 | I17: 4980 | J17: 4185 | K17: 185 | L17: #FutureOfDriving | N17: =(Posts1114[[#This Row],[Likes]]+Posts1114[[#This Row],[Shares]]+Posts1114[[#This Row],[Comments]])/Posts1114[[#This Row],[Impressions]] -> 0.32349398
A18: P224 | B18: Facebook | C18: 45790 | D18: Image | E18: Check out our latest image on facebook! | F18: 602 | G18: 594 | H18: 156 | I18: 4214 | J18: 3363 | K18: 164 | L18: #TeslaCoInnovation | M18: FSDUpdate | N18: =(Posts1114[[#This Row],[Likes]]+Posts1114[[#This Row],[Shares]]+Posts1114[[#This Row],[Comments]])/Posts1114[[#This Row],[Impressions]] -> 0.32083531
A19: P154 | B19: Instagram | C19: 45574 | D19: Carousel | E19: Check out our latest carousel on instagram! | F19: 985 | G19: 932 | H19: 287 | I19: 6895 | J19: 6757 | K19: 64 | L19: #FutureOfDriving | M19: SustainabilityDrive | N19: =(Posts1114[[#This Row],[Likes]]+Posts1114[[#This Row],[Shares]]+Posts1114[[#This Row],[Comments]])/Posts1114[[#This Row],[Impressions]] -> 0.31965192
A20: P119 | B20: Instagram | C20: 45695 | D20: Reel | E20: Check out our latest reel on instagram! | F20: 1970 | G20: 675 | H20: 478 | I20: 9850 | J20: 8924 | K20: 117 | L20: #FutureOfDriving | N20: =(Posts1114[[#This Row],[Likes]]+Posts1114[[#This Row],[Shares]]+Posts1114[[#This Row],[Comments]])/Posts1114[[#This Row],[Impressions]] -> 0.31705584
A21: P287 | B21: Instagram | C21: 45519 | D21: Reel | E21: Check out our latest reel on instagram! | F21: 1164 | G21: 616 | H21: 324 | I21: 6984 | J21: 6636 | K21: 82 | L21: #EVRevolution | M21: CybertruckLaunch | N21: =(Posts1114[[#This Row],[Likes]]+Posts1114[[#This Row],[Shares]]+Posts1114[[#This Row],[Comments]])/Posts1114[[#This Row],[Impressions]] -> 0.30126002
A22: P204 | B22: Instagram | C22: 45658 | D22: Carousel | E22: Check out our latest carousel on instagram! | F22: 2234 | G22: 653 | H22: 432 | I22: 11170 | J22: 10569 | K22: 198 | L22: #FutureOfDriving | M22: FSDUpdate | N22: =(Posts1114[[#This Row],[Likes]]+Posts1114[[#This Row],[Shares]]+Posts1114[[#This Row],[Comments]])/Posts1114[[#This Row],[Impressions]] -> 0.29713518
A23: P066 | B23: Twitter | C23: 45499 | D23: Carousel | E23: Check out our latest carousel on twitter! | F23: 432 | G23: 171 | H23: 280 | I23: 3024 | J23: 2285 | K23: 184 | L23: #EVRevolution | M23: CybertruckLaunch | N23: =(Posts1114[[#This Row],[Likes]]+Posts1114[[#This Row],[Shares]]+Posts1114[[#This Row],[Comments]])/Posts1114[[#This Row],[Impressions]] -> 0.29199735
A24: P183 | B24: Instagram | C24: 45643 | D24: Story | E24: Check out our latest story on instagram! | F24: 360 | G24: 590 | H24: 393 | I24: 4680 | J24: 4322 | K24: 208 | L24: #FutureOfDriving | M24: ModelYCampaign | N24: =(Posts1114[[#This Row],[Likes]]+Posts1114[[#This Row],[Shares]]+Posts1114[[#This Row],[Comments]])/Posts1114[[#This Row],[Impressions]] -> 0.28696581
A25: P031 | B25: Instagram | C25: 45642 | D25: Text | E25: Check out our latest text on instagram! | F25: 438 | G25: 153 | H25: 275 | I25: 3066 | J25: 2701 | K25: 282 | L25: #TeslaCoInnovation | M25: ModelYCampaign | N25: =(Posts1114[[#This Row],[Likes]]+Posts1114[[#This Row],[Shares]]+Posts1114[[#This Row],[Comments]])/Posts1114[[#This Row],[Impressions]] -> 0.28245271
A26: P093 | B26: Instagram | C26: 45637 | D26: Video | E26: Check out our latest video on instagram! | F26: 1431 | G26: 951 | H26: 26 | I26: 8586 | J26: 8396 | K26: 150 | L26: #EVRevolution | M26: FSDUpdate | N26: =(Posts1114[[#This Row],[Likes]]+Posts1114[[#This Row],[Shares]]+Posts1114[[#This Row],[Comments]])/Posts1114[[#This Row],[Impressions]] -> 0.28045656
A27: P263 | B27: Instagram | C27: 45524 | D27: Reel | E27: Check out our latest reel on instagram! | F27: 2603 | G27: 690 | H27: 205 | I27: 13015 | J27: 12130 | K27: 20 | L27: #FutureOfDriving | M27: ModelYCampaign | N27: =(Posts1114[[#This Row],[Likes]]+Posts1114[[#This Row],[Shares]]+Posts1114[[#This Row],[Comments]])/Posts1114[[#This Row],[Impressions]] -> 0.26876681
A28: P248 | B28: Facebook | C28: 45690 | D28: Story | E28: Check out our latest story on facebook! | F28: 886 | G28: 126 | H28: 153 | I28: 4430 | J28: 4037 | K28: 212 | L28: #EVRevolution | N28: =(Posts1114[[#This Row],[Likes]]+Posts1114[[#This Row],[Shares]]+Posts1114[[#This Row],[Comments]])/Posts1114[[#This Row],[Impressions]] -> 0.26297968
A29: P244 | B29: YouTube | C29: 45590 | D29: Video | E29: Check out our latest video on youtube! | F29: 4661 | G29: 935 | H29: 433 | I29: 23305 | J29: 22583 | K29: 63 | L29: #FutureOfDriving | M29: FSDUpdate | N29: =(Posts1114[[#This Row],[Likes]]+Posts1114[[#This Row],[Shares]]+Posts1114[[#This Row],[Comments]])/Posts1114[[#This Row],[Impressions]] -> 0.25869985
A30: P259 | B30: Facebook | C30: 45698 | D30: Text | E30: Check out our latest text on facebook! | F30: 562 | G30: 158 | H30: 149 | I30: 3372 | J30: 2940 | K30: 93 | L30: #TeslaCoInnovation | M30: CybertruckLaunch | N30: =(Posts1114[[#This Row],[Likes]]+Posts1114[[#This Row],[Shares]]+Posts1114[[#This Row],[Comments]])/Posts1114[[#This Row],[Impressions]] -> 0.25771056
